Workbook
Name _Hlk174615379: 'Contract Data'!#REF!
Name _Hlk89177313: 'India - Fix'!$H$47

Sheet Contract Data
AA1: =SUM(AA3:AA26948) -> 461 | AN1: =SUM(AN3:AN26948) -> #VALUE! | AO1: =SUM(AO3:AO26948) -> #VALUE! | AP1: Bank Details
C2: Sn | D2: Date | E2: Basic Comm | F2: BROKER | G2: SF | H2: Buyer Name | I2: Contract No | J2: Customer Address | K2: Add 1 | L2: Country | M2: IEC No | N2: Pan No | O2: GST No | P2: Consignee Code | Q2: Contact No | R2: Email ID | S2: Commodity | T2: HS Code | U2: Origin | V2: POL | W2: POD | X2: Final Place of Delievry | Y2: Charges | Z2: Inco Term | AA2: Qty | AB2: Toll | AC2: Packing | AD2: No of Cont | AE2: FT | AF2: Pay Condition | AG2: Documents | AH2: Price Base | AI2: LME% | AJ2: Fix Price | AK2: Shortage | AL2: Broker | AM2: Brokerage pmt | AN2: Loading Qty | AO2: Balance Qty | AP2: Courier | AQ2: Bank Name | AR2: Address | AS2: Swift | AT2: Contact | AU2: Contact person | AV2: Account No
C3: 001 | D3: 46113 | E3: CU | F3: NIZMET | G3: NS | H3: NINGBO SINO-HK METAL CO., LTD | I3: =CONCATENATE("S/AGFZE/",E3,"/",G3,"/",C3,"/","2026-27") -> S/AGFZE/CU/NS/001/2026-27 | J3: ROOM 308, BLOCK A, TIAN YI BUSINESS CENTER | K3: NO.19 HUALOU XIANG, NB, CHINA | L3: CHINA | P3: USCI CODE: 91330212753280182E, CONTACT PERSON: CAROL | Q3: TEL:0086-574-87275231, FAX:0086-574-87275382 | R3: EMAIL: NINGBOCAROL@126.COM | S3: RECYCLING MATERIAL FOR COPPER | U3: ISRAEL | V3: ISRAEL | W3: NINGBO | Y3: =IF(X3="","","(INLAND HAULAGE CHARGES ON BUYER’S ACCOUNT)") | Z3: CIF | AA3: 40 | AB3: +/-10% | AC3: LOOSE / JUMBO BAGS / BRIQUETTED | AD3: 2 | AE3: 20 | AF3: 100% BY TT BEFORE ARRIVAL OF THE VESSEL AT POD | AG3: 1) FULL SET (3/3) ORIGINAL BILL OF LADING B/L TO SHOW "FREIGHT PREPAID" 2) COMMERCIAL INVOICE 3) PACKING LIST 4) CERTIFICATE OF ORIGIN 5) INSURANCE CERTIFICATE. | AH3: 3 MONTHS CU LME IN US$ | AI3: 98 | AJ3: 0 | AK3: 0.50% | AL3: NIZMET | AM3: 25 | AN3: =SUMIF('[1]2026-27'!$O:$O,I3,'[1]2026-27'!$U:$U) -> #VALUE! | AO3: =AA3-AN3 -> #VALUE!
C4: 002 | D4: 46120 | E4: AL | G4: PO | H4: PARAS OVERSEAS | I4: =CONCATENATE("S/AGFZE/",E4,"/",G4,"/",C4,"/","2026-27") -> S/AGFZE/AL/PO/002/2026-27 | J4: 1008, 10TH FLOOR, SUKHSAGAR COMPLEX, | K4: FORTUNE LANDMARK HOTEL, USMANPURA-380013, AHMEDABAD, INDIA | L4: INDIA | M4: IEC: 0814022944 | N4: PAN: AAQFP6007J | O4: GST: 24AAQFP6007J1Z1 | Q4: TEL: +91-9978050608 | R4: EMAIL: JAINAM@PARASGROUPS.IN | S4: ALUMINIUM SCRAP TALLY AS PER ISRI | T4: HS CODE: 76020010 | U4: DAMMAM VIA JEDDAH, SAUDI ARABIA | V4: SAUDI ARABIA | W4: MUNDRA | X4: ICD AHMEDABAD | Y4: (INLAND HAULAGE CHARGES ON BUYER’S ACCOUNT) | Z4: CIF | AA4: 21 | AB4: +/-10% | AC4: BRIQUETTED | AD4: 1 | AE4: 20 | AF4: 100% CAD THROUGH BANK | AG4: 1) FULL SET (3/3) ORIGINAL BILL OF LADING B/L TO SHOW “FREIGHT PREPAID” 2) COMMERCIAL INVOICE 3) PACKING LIST 4) CERTIFICATE OF ORIGIN 5) INSURANCE CERTIFICATE 6) FREIGHT CERTIFICATE 7) FORM 6 & FORM 9 8) CHEMICAL ANALYSIS CERTIFICATE 9) PSIC CERTIFICATE 10) NO WAR CERTIFICATE. | AI4: 0 | AJ4: 2265 | AK4: 0.50% | AL4: NICRO | AM4: 0 | AN4: =SUMIF('[1]2026-27'!$O:$O,I4,'[1]2026-27'!$U:$U) -> #VALUE! | AO4: =AA4-AN4 -> #VALUE! | AP4: DIRECT TO BANK | AQ4: STATE BANK OF INDIA | AR4: 1008, 10TH FLOOR ,SUKHSAGAR COMPLEX, NEAR FORTUNE LANDMARK HOTEL,USMANPURA-380013, AHMEDABAD, GUJARAT. INDIA | AS4: SWIGT: SBININBB651 | AT4: TEL: +9176000 38681 | AU4: BHAVNA SHAMMI | AV4: A/C NO: 41794675633
C5: 003 | D5: 46136 | E5: CU | G5: NC | H5: NINGBO CIMEI IMPORT & EXPORT CO., LTD | I5: =CONCATENATE("S/AGFZE/",E5,"/",G5,"/",C5,"/","2026-27") -> S/AGFZE/CU/NC/003/2026-27 | J5: 18F, Block A, Ningxing International Trade Building, 510 Heyuan Road, | K5: Yinzhou District, Ningbo, 315040, P.R.C | L5: CHINA | P5: 91330201698240267G | Q5: Tel: 0086-574-87780225 | R5: amy.jiang@futureie.com | S5: Copper Ingots | U5: PAK | W5: NINGBO | Z5: CIF | AA5: 300 | AB5: +/-10% | AC5: LOSSE | AD5: 12 | AE5: 20 | AF5: 100% CAD THROUGH BANK | AG5: 1) FULL SET (3/3) ORIGINAL BILL OF LADING B/L TO SHOW "FREIGHT PREPAID" 2) COMMERCIAL INVOICE 3) PACKING LIST 4) CERTIFICATE OF ORIGIN 5) INSURANCE CERTIFICATE. | AH5: 3 MONTHS CU LME IN US$ | AI5: 96.85 | AK5: 0.50% | AL5: NIZMET | AM5: 25
C6: 004 | D6: 46179 | E6: CU | G6: NC | H6: NINGBO CIMEI IMPORT & EXPORT CO., LTD | I6: =CONCATENATE("S/AGFZE/",E6,"/",G6,"/",C6,"/","2026-27") -> S/AGFZE/CU/NC/004/2026-27 | J6: 18F, Block A, Ningxing International Trade Building, 510 Heyuan Road, | K6: Yinzhou District, Ningbo, 315040, P.R.C | L6: CHINA | P6: 91330201698240267G | Q6: Tel: 0086-574-87780225 | R6: amy.jiang@futureie.com | S6: COPPER INGOTS 99% | T6: HS CODE:74040012 | U6: PAKISTAN | V6: PAKISTAN | W6: NINGBO, | Z6: CIF | AA6: 100 | AB6: +/-10% | AC6: LOSSE | AD6: 5 | AE6: 20 | AF6: 100% CAD THROUGH BANK | AG6: 1) FULL SET (3/3) ORIGINAL BILL OF LADING B/L TO SHOW "FREIGHT PREPAID" 2) COMMERCIAL INVOICE 3) PACKING LIST 4) CERTIFICATE OF ORIGIN 5) INSURANCE CERTIFICATE. | AH6: 3 MONTHS CU LME IN US$ | AI6: 96.85 | AJ6: 5000 | AK6: 0.50%

Sheet India - Fix
A1: Contact No ======> | C1: 632
E6: SALES CONTRACT
F8: =_xlfn.XLOOKUP(C1,'Contract Data'!C:C,'Contract Data'!I:I) -> #N/A
F10: TO
F11: =_xlfn.XLOOKUP(C1,'Contract Data'!C:C,'Contract Data'!H:H) -> #N/A
F12: =_xlfn.XLOOKUP(C1,'Contract Data'!C:C,'Contract Data'!J:J)&", "&_xlfn.XLOOKUP('India - Fix'!C1,'Contract Data'!C:C,'Contract Data'!#REF!)&", "&_xlfn.XLOOKUP('India - Fix'!C1,'Contract Data'!C:C,'Contract Data'!#REF!)&", "&_xlfn.XLOOKUP('India - Fix'!C1,'Contract Data'!C:C,'Contract Data'!M:M)&", "&_xlfn.XLOOKUP('India - Fix'!C1,'Contract Data'!C:C,'Contract Data'!N:N)&", "&_xlfn.XLOOKUP('India - Fix'!C1,'Contract Data'!C:C,'Contract Data'!O:O)&", "&_xlfn.XLOOKUP('India - Fix'!C1,'Contract Data'!C:C,'Contract Data'!Q:Q)&", "&_xlfn.XLOOKUP('India - Fix'!C1,'Contract Data'!C:C,'Contract Data'!R:R)&", "&_xlfn.XLOOKUP('India - Fix'!C1,'Contract Data'!C:C,'Contract Data'!S:S) -> #N/A
F19: WE CONFIRM HAVING SOLD TO YOU THE FOLLOWING:
F21: 1. | G21: COMMODITY
G22: 1.1 | H22: ALUMINIUM SCRAP TROMA AS PER ISRI (HS CODE 76020010)
G23: 1.2 | H23: THE CONSIGNMENT DOES NOT CONTAIN ANY TYPE OF ARMS, AMMUNITIONS, MINES, SHELLS, CARTRIDGES, RADIOACTIVE CONTAMINATED OR ANY OTHER EXPLOSIVE MATERIAL IN ANY FORM EITHER USED OR OTHERWISE.
G24: 1.3 | H24: ORIGIN :
G25: 1.4 | H25: LOAD PORT
G26: 1.5
G27: 1.6
F29: 2. | G29: PAYAMENT CONDITIONS: 100% CAD THROUGH BANK AGAINST FOLLOWING DOCUMENTS:
G30: 1) FULL SET (3/3) ORIGINAL BILL OF LADING B/L TO SHOW “FREIGHT PREPAID” 2) COMMERCIAL INVOICE 3) PACKING LIST 4) CERTIFICATE OF ORIGIN 5) INSURANCE CERTIFICATE 6) FREIGHT CERTIFICATE 7) FORM 6 & FORM 9 8) CHEMICAL ANALYSIS CERTIFICATE 9) PSIC CERTIFICATE 10) NO WAR CERTIFICATE.
F32: 3. | G32: PRICE: USD 2,835.00 CIF MUNDRA, INDIA. ICD PATLI.
F34: 4. | G34: SHIPMENT PERIOD: LOADING WILL BE IN 45 AFTER SIGNED CONTRACT AND ADVANCE PAYMENT IN OUR ACCOUNT (IF APPLICABLE), SHIPMENT WILL BE ON 1ST AVAILABLE VESSEL (SUBJECT TO NO LOCKDOWN OR ANY UNFORESEEN CIRCUMSTANCES AT POL).
F36: 5. | G36: INSURANCE: THE SELLER SHALL COVER THE INSURANCE AT THEIR COST. THE INSURANCE CLAUSE SHOULD BE AS UNDER: “MARINE INSURANCE POLICY / CERTIFICATE FOR ATLEAST 10% OVER THE INVOICE VALUE, DATED NOT LATER THAN THE DATE OF BILL OF LADING COVERING INSTITUTE CARGO CLAUSE [A]” WITH COVERAGE FOR THE THEFT AND PILFERAGE.
F38: 6. | G38: ARBITRATION AND GOVERNING LAW: ANY DISPUTES ARISING OUT OF OR IN CONNECTION WITH THIS CONTRACT, INCLUDING ANY QUESTION REGARDING ITS EXECUTION, VALIDITY OR TERMINATION, WHICH THE PARTIES FAIL TO RESOLVE AMICABLY, SHALL BE REFERRED TO AND FINALLY RESOLVED BY ARBITRATION UNDER THE UK RULES ON THIS SUBJECT.
F40: 7. | G40: FORCE MAJEURE: SUCH AS FIRE, FLOOD, BREAKDOWN, ACCIDENT, WAR, INSURRECTION, RIOT, GOVERNMENTAL ACTION, LABOR DISPUTE, SHORTAGE OF FUEL, ELECTRICITY, RAW MATERIALS OR SUPPLIES, LACK OF FREIGHT FACILITIES, CAUSED BY ANY ACT OF GOD OR ANY OTHER CAUSE BEYOND THE REASONABLE CONTROL OF THE SELLER OR ADANI GLOBAL FZE, THE ARRANGEMENTS AND OBLIGATIONS OF THE CONTRACT ARE SUSPENDED COMPLETELY OR PARTIALLY, DEPENDING ON THE EXTENT OF THE HINDRANCE, FOR THE DURATION OF THE FORCE MAJEURE FROM THE MOMENT IN WHICH THE AFFECTED PARTY INFORMS THE OTHER ABOUT THE EXISTENCE OF FORCE MAJEURE IN WRITING, INCLUDING THE REASON FOR IT.
G41: IN THE CASE OF FORCE MAJEURE AT ADANI GLOBAL FZE, DELIVERIES ARE ONLY PERMITTED WITH ADANI GLOBAL FZE EXPRESS AGREEMENT. A SUSPENSION OF PERFORMANCE SHALL NOT HAVE THE EFFECT OF CANCELLING THE CONTRACT, WHICH SHALL AGAIN COME INTO FULL FORCE AND EFFECT IMMEDIATELY UPON TERMINATION OF THE FORCE MAJEURE EVENT. THE CONTRACT SHALL, EACH TIME, BE EXTENDED FOR A PERIOD EQUAL TO THE PERIOD OF SUSPENSION.
E44: اداني دجلوبال م م ح | F44: اداني دجلوبال م م ح
E45: Adani Global FZE Tel: +971 4 3611900
E46: Post Box 17186, Fax: +971 4 3689600
E47: Jebel Ali, Email: commercial.dxb@adani.in
E48: Dubai, UAE www.adani.com
F50: ذات مسئولية محدودة تأسست بموجب القانون رقم 9 لسنة 1992
F51: Formed pursuant to Law No.9 of 1992 With Limited Liability
F57: =F8 -> #N/A
H58: =F9 -> 0
G59: IF A CASE OF FORCE MAJEURE LASTS LONGER THAN THREE MONTHS FROM THE TIME IT IS ANNOUNCED, EACH SELLER HAS THE RIGHT TO RESCIND THE CONTRACT WITH RESPECT TO THE VOLUMES THAT WERE NOT DELIVERED AND/OR ACCEPTED DUE TO THE FORCE MAJEURE.
G61: NOTWITHSTANDING THE FOREGOING PROVISIONS SHOULD THE PRICE OF THE METALS, WHICH DELIVERY WAS SUSPENDED DUE TO AN EVENT OF FORCE MAJEURE, HAVE ALREADY BEEN FIXED, THEN SUCH PRICE IS APPLIED TO THE MATERIAL TO BE FIRST DELIVERED AFTER THE DELIVERY THEREOF IS RESUMED
F63: 8. | G63: IF THERE IS A VARIATION IN THE QUALITY AND QUANTITY AT DISCHARGE PORT, A THIRD PARTY MUTUALLY AGREED INSPECTION AGENCY WILL BE APPOINTED AND THEIR RESULT WILL BE TAKEN AS A FINAL AND LOOSING PARTY WILL PAY THE CHARGES AND SETTLE THE CLAIM TO BUYER / SELLER.
F65: 9. | G65: ALL KIND OF TAXES / DUTIES/LEVIES ETC. IN IMPORTING COUNTRY TO BE BORNE BY THE BUYER.
F67: 10. | G67: WEIGHT SHORTAGE WILL NOT BE ACCEPTED LESS THAN 0.5%, MORE THAN 0.5% WILL BE CLAIMED.
G69: ALL BANK CHARGES OUTSIDE UAE INCLUDING CORRESPONDENCE BANK CHARGES WILL BE IN BUYER'S ACCOUNT, ACTUAL AMOUNT RECEIVED THROUGH ADVANCE / DEPOSIT WILL BE CONSIDERED AND ADJUSTED IN THE INVOICE ACCORDINGLY.
G71: US SANCTIONS COMPLIANCE: EACH PARTY REPRESENTS AND WARRANTS THAT IT IS NOT A SANCTIONED PERSON AND SHALL COMPLY WITH ALL APPLICABLE U.S. SANCTIONS LAWS AND REGULATIONS. NEITHER PARTY SHALL ENGAGE IN ANY TRANSACTION UNDER THIS CONTRACT THAT WOULD CAUSE EITHER PARTY TO VIOLATE U.S. SANCTIONS, INCLUDING DEALINGS WITH SANCTIONED ENTITIES OR RESTRICTED JURISDICTIONS. IF COMPLIANCE BECOMES UNLAWFUL, THE AFFECTED PARTY MAY SUSPEND OR TERMINATE PERFORMANCE WITHOUT LIABILITY.
F73: THE SELLER | H73: THE BUYER
F75: FOR ADANI GLOBAL FZE. | H75: FOR SHREE BALAJI ALUMNICAST PVT LTD
...

Sheet INDIA (QP)
A1: 002
D6: SALES CONTRACT
D8: =_xlfn.XLOOKUP(A1,'Contract Data'!C:C,'Contract Data'!I:I) -> S/AGFZE/AL/PO/002/2026-27 | O8: ="DATE: "&TEXT(_xlfn.XLOOKUP(A1,'Contract Data'!C:C,'Contract Data'!D:D),"dd/mm/yyyy") -> DATE: 08/04/2026
D10: =_xlfn.XLOOKUP(A1,'Contract Data'!C:C,'Contract Data'!H:H) -> PARAS OVERSEAS
D11: =_xlfn.XLOOKUP(A1,'Contract Data'!C:C,'Contract Data'!J:J)&_xlfn.XLOOKUP(A1,'Contract Data'!C:C,'Contract Data'!K:K) -> 1008, 10TH FLOOR, SUKHSAGAR COMPLEX, FORTUNE LANDMARK HOTEL, USMANPURA-380013, AHMEDABAD, INDIA
D12: =_xlfn.XLOOKUP(A1,'Contract Data'!C:C,'Contract Data'!M:M)&", "&_xlfn.XLOOKUP(A1,'Contract Data'!C:C,'Contract Data'!N:N)&", "&_xlfn.XLOOKUP(A1,'Contract Data'!C:C,'Contract Data'!O:O)&", "&_xlfn.XLOOKUP(A1,'Contract Data'!C:C,'Contract Data'!R:R)&", "&_xlfn.XLOOKUP(A1,'Contract Data'!C:C,'Contract Data'!Q:Q) -> IEC: 0814022944, PAN: AAQFP6007J, GST: 24AAQFP6007J1Z1, EMAIL: JAINAM@PARASGROUPS.IN, TEL: +91-9978050608
D13: WE CONFIRM HAVING SOLD TO YOU THE FOLLOWING:
D15: 1. | E15: COMMODITY
E16: 1.1. | F16: =_xlfn.XLOOKUP(A1,'Contract Data'!C:C,'Contract Data'!S:S)&" (HS CODE: "&_xlfn.XLOOKUP(A1,'Contract Data'!C:C,'Contract Data'!T:T)&" )" -> ALUMINIUM SCRAP TALLY AS PER ISRI (HS CODE: HS CODE: 76020010 )
E17: 1.2. | F17: THE CONSIGNMENT DOES NOT CONTAIN ANY TYPE OF ARMS, AMMUNITIONS, MINES, SHELLS, HAZARDOUS WASTE, CARTRIDGES, RADIOACTIVE CONTAMINATED OR ANY OTHER EXPLOSIVE OR PROHIBITED MATERIAL IN ANY FORM, WHETHER USED OR UNUSED, AND IS SAFE FOR TRANSPORT AND HANDLING.
E18: 1.3. | F18: ORIGIN : | H18: =_xlfn.XLOOKUP(A1,'Contract Data'!C:C,'Contract Data'!U:U) -> DAMMAM VIA JEDDAH, SAUDI ARABIA
E19: 1.4. | F19: LOAD PORT : | H19: ="ANY PORT (S) IN "&_xlfn.XLOOKUP(A1,'Contract Data'!C:C,'Contract Data'!V:V) -> ANY PORT (S) IN SAUDI ARABIA
E20: 1.5. | F20: PLACE OF DELIVERY : | H20: =_xlfn.XLOOKUP(A1,'Contract Data'!C:C,'Contract Data'!Z:Z)&", "&_xlfn.XLOOKUP(A1,'Contract Data'!C:C,'Contract Data'!W:W)&", "&_xlfn.XLOOKUP(A1,'Contract Data'!C:C,'Contract Data'!X:X)&", "&_xlfn.XLOOKUP(A1,'Contract Data'!C:C,'Contract Data'!L:L)&", "&_xlfn.XLOOKUP(A1,'Contract Data'!C:C,'Contract Data'!Y:Y) -> CIF, MUNDRA, ICD AHMEDABAD, INDIA, (INLAND HAULAGE CHARGES ON BUYER’S ACCOUNT)
E21: 1.6. | F21: QUANTITY & PACKING: | H21: =_xlfn.XLOOKUP(A1,'Contract Data'!C:C,'Contract Data'!AA:AA)&" MT "&_xlfn.XLOOKUP(A1,'Contract Data'!C:C,'Contract Data'!AB:AB)&" (SELLER’S OPTION) IN "&_xlfn.XLOOKUP(A1,'Contract Data'!C:C,'Contract Data'!AC:AC)&" IN "&_xlfn.XLOOKUP(A1,'Contract Data'!C:C,'Contract Data'!AD:AD)&" X "&_xlfn.XLOOKUP(A1,'Contract Data'!C:C,'Contract Data'!AE:AE)&" CONTAINER/S" -> 21 MT +/-10% (SELLER’S OPTION) IN BRIQUETTED IN 1 X 20 CONTAINER/S
D23: 2. | E23: PAYMENT CONDITIONS : | H23: =_xlfn.XLOOKUP(A1,'Contract Data'!C:C,'Contract Data'!AF:AF)&" AGAINST FOLLOWING DOCUMENTS" -> 100% CAD THROUGH BANK AGAINST FOLLOWING DOCUMENTS
E24: =_xlfn.XLOOKUP(A1,'Contract Data'!C:C,'Contract Data'!AG:AG) -> 1) FULL SET (3/3) ORIGINAL BILL OF LADING B/L TO SHOW “FREIGHT PREPAID” 2) COMMERCIAL INVOICE 3) PACKING LIST 4) CERTIFICATE OF ORIGIN 5) INSURANCE CERTIFICATE 6) FREIGHT CERTIFICATE 7) FORM 6 & FORM 9 8) CHEMICAL ANALYSIS CERTIFICATE 9) PSIC CERTIFICATE 10) NO WAR CERTIFICATE.
D26: 3. | E26: ="PRICE: "&_xlfn.XLOOKUP('INDIA (QP)'!A1,'Contract Data'!C:C,'Contract Data'!AH:AH)&", TO BE FIXED BY BUYER, EITHER ON OFFICIAL SETTLEMENT OR ON RUNNING SCREEN OR GTC WITHIN SPECIFIED Q/P X "&_xlfn.XLOOKUP(A1,'Contract Data'!C:C,'Contract Data'!AI:AI)&" %"&" "&_xlfn.XLOOKUP(A1,'Contract Data'!C:C,'Contract Data'!Z:Z)&" "&_xlfn.XLOOKUP(A1,'Contract Data'!C:C,'Contract Data'!W:W)&", "&_xlfn.XLOOKUP(A1,'Contract Data'!C:C,'Contract Data'!X:X)&", "&_xlfn.XLOOKUP(A1,'Contract Data'!C:C,'Contract Data'!L:L) -> PRICE: , TO BE FIXED BY BUYER, EITHER ON OFFICIAL SETTLEMENT OR ON RUNNING SCREEN OR GTC WITHIN SPECIFIED Q/P X 0 % CIF MUNDRA, ICD AHMEDABAD, INDIA
D28: 4. | E28: Q/P: ANY UNKNOWN LME WORKING DAY, FROM BUSINESS CONFIRMATION DATE TILL ETA.
D30: 5. | E30: SHIPMENT PERIOD: LOADING WILL BE WITHIN 45 DAYS FROM THE DATE OF RECEIPT OF SIGNED CONTRACT AND ADVANCE PAYMENT IN OUR ACCOUNT (IF APPLICABLE), SHIPMENT WILL BE ON 1ST AVAILABLE VESSEL (SUBJECT TO NO LOCKDOWN OR ANY UNFORESEEN CIRCUMSTANCES AT POL).
D32: 6. | E32: INSURANCE: THE SELLER SHALL COVER THE INSURANCE AT THEIR COST. THE INSURANCE CLAUSE SHOULD BE AS UNDER: “MARINE INSURANCE POLICY / CERTIFICATE FOR ATLEAST 10% OVER THE INVOICE VALUE, DATED NOT LATER THAN THE DATE OF BILL OF LADING COVERING INSTITUTE CARGO CLAUSE [A]” WITH COVERAGE FOR THE THEFT AND PILFERAGE.
D33: 7. | E33: ARBITRATION AND GOVERNING LAW: ANY DISPUTES ARISING OUT OF OR IN CONNECTION WITH THIS CONTRACT, INCLUDING ANY QUESTION REGARDING ITS EXECUTION, VALIDITY OR TERMINATION, WHICH THE PARTIES FAIL TO RESOLVE AMICABLY, SHALL BE REFERRED TO AND FINALLY RESOLVED BY ARBITRATION UNDER THE SIAC (SINGAPORE INTERNATIONAL ARBITRATION CENTRE) OR DIFC (DUBAI INTERNATIONAL FINANCIAL CENTRE) OR LCIA (THE LONDON COURT OF INTERNATIONAL ARBITRATION) ON THIS SUBJECT.
D34: 8. | E34: FORCE MAJEURE: SUCH AS FIRE, FLOOD, BREAKDOWN, ACCIDENT, WAR, INSURRECTION, RIOT, GOVERNMENTAL ACTION, LABOR DISPUTE, SHORTAGE OF FUEL, ELECTRICITY, RAW MATERIALS OR SUPPLIES, LACK OF FREIGHT FACILITIES, CAUSED BY ANY ACT OF GOD OR ANY OTHER CAUSE BEYOND THE REASONABLE CONTROL OF THE SELLER OR ADANI GLOBAL FZE, THE ARRANGEMENTS AND OBLIGATIONS OF THE CONTRACT ARE SUSPENDED COMPLETELY OR PARTIALLY, DEPENDING ON THE EXTENT OF THE HINDRANCE, FOR THE DURATION OF THE FORCE MAJEURE FROM THE MOMENT IN WHICH THE AFFECTED PARTY INFORMS THE OTHER ABOUT THE EXISTENCE OF FORCE MAJEURE IN WRITING, INCLUDING THE REASON FOR IT.
D37: اداني دجلوبال م م ح
D38: Adani Global FZE | G38: Tel: +971 4 3611900
D39: Post Box 17186, | G39: Fax: +971 4 3689600
D40: Jebel Ali, | G40: Email: commercial.dxb@adani.in
D41: Dubai, UAE | G41: www.adani.com
D43: ذات مسئولية محدودة تأسست بموجب القانون رقم 9 لسنة 1992
D44: Formed pursuant to Law No.9 of 1992 With Limited Liability
D53: =D8 -> S/AGFZE/AL/PO/002/2026-27 | O53: =O8 -> DATE: 08/04/2026
E55: IN THE CASE OF FORCE MAJEURE AT ADANI GLOBAL FZE, DELIVERIES ARE ONLY PERMITTED WITH ADANI GLOBAL FZE EXPRESS AGREEMENT. A SUSPENSION OF PERFORMANCE SHALL NOT HAVE THE EFFECT OF CANCELLING THE CONTRACT, WHICH SHALL AGAIN COME INTO FULL FORCE AND EFFECT IMMEDIATELY UPON TERMINATION OF THE FORCE MAJEURE EVENT. THE CONTRACT SHALL, EACH TIME, BE EXTENDED FOR A PERIOD EQUAL TO THE PERIOD OF SUSPENSION.
E56: IF A CASE OF FORCE MAJEURE LASTS LONGER THAN THREE MONTHS FROM THE TIME IT IS ANNOUNCED, EACH SELLER HAS THE RIGHT TO RESCIND THE CONTRACT WITH RESPECT TO THE VOLUMES THAT WERE NOT DELIVERED AND/OR ACCEPTED DUE TO THE FORCE MAJEURE.
E57: NOTWITHSTANDING THE FOREGOING PROVISIONS SHOULD THE PRICE OF THE METALS, WHICH DELIVERY WAS SUSPENDED DUE TO AN EVENT OF FORCE MAJEURE, HAVE ALREADY BEEN FIXED, THEN SUCH PRICE IS APPLIED TO THE MATERIAL TO BE FIRST DELIVERED AFTER THE DELIVERY THEREOF IS RESUMED.
D59: 9. | E59: IF THERE IS A VARIATION IN THE QUALITY AND QUANTITY AT DISCHARGE PORT, A THIRD PARTY MUTUALLY AGREED INSPECTION AGENCY WILL BE APPOINTED AND THEIR RESULT WILL BE TAKEN AS A FINAL AND LOOSING PARTY WILL PAY THE CHARGES AND SETTLE THE CLAIM TO BUYER / SELLER.
D61: 10. | E61: ALL KIND OF TAXES / DUTIES/LEVIES ETC. IN IMPORTING COUNTRY TO BE BORNE BY THE BUYER.
D63: 11. | E63: ="WEIGHT SHORTAGE WILL NOT BE ACCEPTED LESS THAN "&_xlfn.XLOOKUP(A1,'Contract Data'!C:C,'Contract Data'!AK:AK)&", MORE THAN "&_xlfn.XLOOKUP(A1,'Contract Data'!C:C,'Contract Data'!AK:AK)&" WILL BE CLAIMED" -> WEIGHT SHORTAGE WILL NOT BE ACCEPTED LESS THAN 0.50%, MORE THAN 0.50% WILL BE CLAIMED
D65: 12. | E65: ALL BANK CHARGES OUTSIDE UAE INCLUDING CORRESPONDENCE BANK CHARGES WILL BE IN BUYER'S ACCOUNT, ACTUAL AMOUNT RECEIVED THROUGH ADVANCE / DEPOSIT WILL BE CONSIDERED AND ADJUSTED IN THE INVOICE ACCORDINGLY.
D67: 13. | E67: US SANCTIONS COMPLIANCE: EACH PARTY REPRESENTS AND WARRANTS THAT IT IS NOT A SANCTIONED PERSON AND SHALL COMPLY WITH ALL APPLICABLE U.S. SANCTIONS LAWS AND REGULATIONS. NEITHER PARTY SHALL ENGAGE IN ANY TRANSACTION UNDER THIS CONTRACT THAT WOULD CAUSE EITHER PARTY TO VIOLATE U.S. SANCTIONS, INCLUDING DEALINGS WITH SANCTIONED ENTITIES OR RESTRICTED JURISDICTIONS. IF COMPLIANCE BECOMES UNLAWFUL, THE AFFECTED PARTY MAY SUSPEND OR TERMINATE PERFORMANCE WITHOUT LIABILITY.
D70: THE SELLER | N70: THE BUYER
D72: FOR ADANI GLOBAL FZE. | N72: ="FOR "&D10 -> FOR PARAS OVERSEAS
...

Sheet INDIA (FIXED RATE)
A1: 002
D6: SALES CONTRACT
D8: =_xlfn.XLOOKUP(A1,'Contract Data'!C:C,'Contract Data'!I:I) -> S/AGFZE/AL/PO/002/2026-27 | O8: ="DATE: "&TEXT(_xlfn.XLOOKUP(A1,'Contract Data'!C:C,'Contract Data'!D:D),"dd/mm/yyyy") -> DATE: 08/04/2026
D10: =_xlfn.XLOOKUP(A1,'Contract Data'!C:C,'Contract Data'!H:H) -> PARAS OVERSEAS
D11: =_xlfn.XLOOKUP(A1,'Contract Data'!C:C,'Contract Data'!J:J) & _xlfn.XLOOKUP(A1,'Contract Data'!C:C,'Contract Data'!K:K) -> 1008, 10TH FLOOR, SUKHSAGAR COMPLEX, FORTUNE LANDMARK HOTEL, USMANPURA-380013, AHMEDABAD, INDIA
D12: =_xlfn.XLOOKUP(A1,'Contract Data'!C:C,'Contract Data'!M:M)&", "&_xlfn.XLOOKUP(A1,'Contract Data'!C:C,'Contract Data'!N:N)&", "&_xlfn.XLOOKUP(A1,'Contract Data'!C:C,'Contract Data'!O:O)&", "&_xlfn.XLOOKUP(A1,'Contract Data'!C:C,'Contract Data'!R:R)&", "&_xlfn.XLOOKUP(A1,'Contract Data'!C:C,'Contract Data'!Q:Q) -> IEC: 0814022944, PAN: AAQFP6007J, GST: 24AAQFP6007J1Z1, EMAIL: JAINAM@PARASGROUPS.IN, TEL: +91-9978050608
D13: WE CONFIRM HAVING SOLD TO YOU THE FOLLOWING:
D15: 1. | E15: COMMODITY
E16: 1.1. | F16: =_xlfn.XLOOKUP(A1,'Contract Data'!C:C,'Contract Data'!S:S)&" (HS CODE: "&_xlfn.XLOOKUP(A1,'Contract Data'!C:C,'Contract Data'!T:T)&")" -> ALUMINIUM SCRAP TALLY AS PER ISRI (HS CODE: HS CODE: 76020010)
E17: 1.2. | F17: THE CONSIGNMENT DOES NOT CONTAIN ANY TYPE OF ARMS, AMMUNITIONS, MINES, SHELLS, HAZARDOUS WASTE, CARTRIDGES, RADIOACTIVE CONTAMINATED OR ANY OTHER EXPLOSIVE OR PROHIBITED MATERIAL IN ANY FORM, WHETHER USED OR UNUSED, AND IS SAFE FOR TRANSPORT AND HANDLING.
E18: 1.3. | F18: ORIGIN : | H18: =_xlfn.XLOOKUP(A1,'Contract Data'!C:C,'Contract Data'!U:U) -> DAMMAM VIA JEDDAH, SAUDI ARABIA
E19: 1.4. | F19: LOAD PORT : | H19: ="ANY PORT (S) IN "&_xlfn.XLOOKUP(A1,'Contract Data'!C:C,'Contract Data'!V:V) -> ANY PORT (S) IN SAUDI ARABIA
E20: 1.5. | F20: PLACE OF DELIVERY : | H20: =_xlfn.XLOOKUP(A1,'Contract Data'!C:C,'Contract Data'!Z:Z)&", "&_xlfn.XLOOKUP(A1,'Contract Data'!C:C,'Contract Data'!W:W)&" "&_xlfn.XLOOKUP(A1,'Contract Data'!C:C,'Contract Data'!X:X)&", "&_xlfn.XLOOKUP(A1,'Contract Data'!C:C,'Contract Data'!L:L)&", "&_xlfn.XLOOKUP(A1,'Contract Data'!C:C,'Contract Data'!Y:Y) -> CIF, MUNDRA ICD AHMEDABAD, INDIA, (INLAND HAULAGE CHARGES ON BUYER’S ACCOUNT)
E21: 1.6. | F21: QUANTITY & PACKING: | H21: =_xlfn.XLOOKUP(A1,'Contract Data'!C:C,'Contract Data'!AA:AA)&" MT "&_xlfn.XLOOKUP(A1,'Contract Data'!C:C,'Contract Data'!AB:AB)&" (SELLER’S OPTION) IN "&_xlfn.XLOOKUP(A1,'Contract Data'!C:C,'Contract Data'!AC:AC)&" IN "&_xlfn.XLOOKUP(A1,'Contract Data'!C:C,'Contract Data'!AD:AD)&" X "&_xlfn.XLOOKUP(A1,'Contract Data'!C:C,'Contract Data'!AE:AE)&" CONTAINER/S" -> 21 MT +/-10% (SELLER’S OPTION) IN BRIQUETTED IN 1 X 20 CONTAINER/S
D23: 2. | E23: PAYMENT CONDITIONS : | H23: =_xlfn.XLOOKUP(A1,'Contract Data'!C:C,'Contract Data'!AF:AF)&" AGAINST FOLLOWING DOCUMENTS" -> 100% CAD THROUGH BANK AGAINST FOLLOWING DOCUMENTS
E24: =_xlfn.XLOOKUP(A1,'Contract Data'!C:C,'Contract Data'!AG:AG) -> 1) FULL SET (3/3) ORIGINAL BILL OF LADING B/L TO SHOW “FREIGHT PREPAID” 2) COMMERCIAL INVOICE 3) PACKING LIST 4) CERTIFICATE OF ORIGIN 5) INSURANCE CERTIFICATE 6) FREIGHT CERTIFICATE 7) FORM 6 & FORM 9 8) CHEMICAL ANALYSIS CERTIFICATE 9) PSIC CERTIFICATE 10) NO WAR CERTIFICATE.
D26: 3. | E26: ="PRICE : USD "&_xlfn.XLOOKUP(A1,'Contract Data'!C:C,'Contract Data'!AJ:AJ)&" PMT"&", "&_xlfn.XLOOKUP(A1,'Contract Data'!C:C,'Contract Data'!Z:Z)&" "&_xlfn.XLOOKUP(A1,'Contract Data'!C:C,'Contract Data'!W:W)&", "&_xlfn.XLOOKUP(A1,'Contract Data'!C:C,'Contract Data'!X:X)&" "&_xlfn.XLOOKUP(A1,'Contract Data'!C:C,'Contract Data'!L:L) -> PRICE : USD 2265 PMT, CIF MUNDRA, ICD AHMEDABAD INDIA
D28: 4. | E28: SHIPMENT PERIOD: LOADING WILL BE WITHIN 45 DAYS FROM THE DATE OF RECEIPT OF SIGNED CONTRACT AND ADVANCE PAYMENT IN OUR ACCOUNT (IF APPLICABLE), SHIPMENT WILL BE ON 1ST AVAILABLE VESSEL (SUBJECT TO NO LOCKDOWN OR ANY UNFORESEEN CIRCUMSTANCES AT POL).
D30: 5. | E30: INSURANCE: THE SELLER SHALL COVER THE INSURANCE AT THEIR COST. THE INSURANCE CLAUSE SHOULD BE AS UNDER: “MARINE INSURANCE POLICY / CERTIFICATE FOR ATLEAST 10% OVER THE INVOICE VALUE, DATED NOT LATER THAN THE DATE OF BILL OF LADING COVERING INSTITUTE CARGO CLAUSE [A]” WITH COVERAGE FOR THE THEFT AND PILFERAGE.
D31: 6. | E31: ARBITRATION AND GOVERNING LAW: ANY DISPUTES ARISING OUT OF OR IN CONNECTION WITH THIS CONTRACT, INCLUDING ANY QUESTION REGARDING ITS EXECUTION, VALIDITY OR TERMINATION, WHICH THE PARTIES FAIL TO RESOLVE AMICABLY, SHALL BE REFERRED TO AND FINALLY RESOLVED BY ARBITRATION UNDER THE SIAC (SINGAPORE INTERNATIONAL ARBITRATION CENTRE) OR DIFC (DUBAI INTERNATIONAL FINANCIAL CENTRE) OR LCIA (THE LONDON COURT OF INTERNATIONAL ARBITRATION) ON THIS SUBJECT.
D32: 7. | E32: FORCE MAJEURE: SUCH AS FIRE, FLOOD, BREAKDOWN, ACCIDENT, WAR, INSURRECTION, RIOT, GOVERNMENTAL ACTION, LABOR DISPUTE, SHORTAGE OF FUEL, ELECTRICITY, RAW MATERIALS OR SUPPLIES, LACK OF FREIGHT FACILITIES, CAUSED BY ANY ACT OF GOD OR ANY OTHER CAUSE BEYOND THE REASONABLE CONTROL OF THE SELLER OR ADANI GLOBAL FZE, THE ARRANGEMENTS AND OBLIGATIONS OF THE CONTRACT ARE SUSPENDED COMPLETELY OR PARTIALLY, DEPENDING ON THE EXTENT OF THE HINDRANCE, FOR THE DURATION OF THE FORCE MAJEURE FROM THE MOMENT IN WHICH THE AFFECTED PARTY INFORMS THE OTHER ABOUT THE EXISTENCE OF FORCE MAJEURE IN WRITING, INCLUDING THE REASON FOR IT.
D35: اداني دجلوبال م م ح
D36: Adani Global FZE | G36: Tel: +971 4 3611900
D37: Post Box 17186, | G37: Fax: +971 4 3689600
D38: Jebel Ali, | G38: Email: commercial.dxb@adani.in
D39: Dubai, UAE | G39: www.adani.com
D41: ذات مسئولية محدودة تأسست بموجب القانون رقم 9 لسنة 1992
D42: Formed pursuant to Law No.9 of 1992 With Limited Liability
D51: =D8 -> S/AGFZE/AL/PO/002/2026-27 | O51: =O8 -> DATE: 08/04/2026
E53: IN THE CASE OF FORCE MAJEURE AT ADANI GLOBAL FZE, DELIVERIES ARE ONLY PERMITTED WITH ADANI GLOBAL FZE EXPRESS AGREEMENT. A SUSPENSION OF PERFORMANCE SHALL NOT HAVE THE EFFECT OF CANCELLING THE CONTRACT, WHICH SHALL AGAIN COME INTO FULL FORCE AND EFFECT IMMEDIATELY UPON TERMINATION OF THE FORCE MAJEURE EVENT. THE CONTRACT SHALL, EACH TIME, BE EXTENDED FOR A PERIOD EQUAL TO THE PERIOD OF SUSPENSION.
E54: IF A CASE OF FORCE MAJEURE LASTS LONGER THAN THREE MONTHS FROM THE TIME IT IS ANNOUNCED, EACH SELLER HAS THE RIGHT TO RESCIND THE CONTRACT WITH RESPECT TO THE VOLUMES THAT WERE NOT DELIVERED AND/OR ACCEPTED DUE TO THE FORCE MAJEURE.
E55: NOTWITHSTANDING THE FOREGOING PROVISIONS SHOULD THE PRICE OF THE METALS, WHICH DELIVERY WAS SUSPENDED DUE TO AN EVENT OF FORCE MAJEURE, HAVE ALREADY BEEN FIXED, THEN SUCH PRICE IS APPLIED TO THE MATERIAL TO BE FIRST DELIVERED AFTER THE DELIVERY THEREOF IS RESUMED.
D57: 8. | E57: IF THERE IS A VARIATION IN THE QUALITY AND QUANTITY AT DISCHARGE PORT, A THIRD PARTY MUTUALLY AGREED INSPECTION AGENCY WILL BE APPOINTED AND THEIR RESULT WILL BE TAKEN AS A FINAL AND LOOSING PARTY WILL PAY THE CHARGES AND SETTLE THE CLAIM TO BUYER / SELLER.
D59: 09. | E59: ALL KIND OF TAXES / DUTIES/LEVIES ETC. IN IMPORTING COUNTRY TO BE BORNE BY THE BUYER.
D61: 10. | E61: ="WEIGHT SHORTAGE WILL NOT BE ACCEPTED LESS THAN "&_xlfn.XLOOKUP(A1,'Contract Data'!C:C,'Contract Data'!AK:AK)&", MORE THAN "&_xlfn.XLOOKUP(A1,'Contract Data'!C:C,'Contract Data'!AK:AK)&" WILL BE CLAIMED" -> WEIGHT SHORTAGE WILL NOT BE ACCEPTED LESS THAN 0.50%, MORE THAN 0.50% WILL BE CLAIMED
D63: 11. | E63: ALL BANK CHARGES OUTSIDE UAE INCLUDING CORRESPONDENCE BANK CHARGES WILL BE IN BUYER'S ACCOUNT, ACTUAL AMOUNT RECEIVED THROUGH ADVANCE / DEPOSIT WILL BE CONSIDERED AND ADJUSTED IN THE INVOICE ACCORDINGLY.
D65: 12. | E65: US SANCTIONS COMPLIANCE: EACH PARTY REPRESENTS AND WARRANTS THAT IT IS NOT A SANCTIONED PERSON AND SHALL COMPLY WITH ALL APPLICABLE U.S. SANCTIONS LAWS AND REGULATIONS. NEITHER PARTY SHALL ENGAGE IN ANY TRANSACTION UNDER THIS CONTRACT THAT WOULD CAUSE EITHER PARTY TO VIOLATE U.S. SANCTIONS, INCLUDING DEALINGS WITH SANCTIONED ENTITIES OR RESTRICTED JURISDICTIONS. IF COMPLIANCE BECOMES UNLAWFUL, THE AFFECTED PARTY MAY SUSPEND OR TERMINATE PERFORMANCE WITHOUT LIABILITY.
D68: THE SELLER | N68: THE BUYER
D70: FOR ADANI GLOBAL FZE. | N70: ="FOR "&D10 -> FOR PARAS OVERSEAS
D74: AUTHORIZED SIGNATORY | N74: AUTHORIZED SIGNATORY
...

Sheet CHINA (QP)
A1: 004
D6: SALES CONTRACT
D8: =_xlfn.XLOOKUP(A1,'Contract Data'!C:C,'Contract Data'!I:I) -> S/AGFZE/CU/NC/004/2026-27 | O8: ="DATE: "&TEXT(_xlfn.XLOOKUP(A1,'Contract Data'!C:C,'Contract Data'!D:D),"dd/mm/yyyy") -> DATE: 06/06/2026
D10: =_xlfn.XLOOKUP(A1,'Contract Data'!C:C,'Contract Data'!H:H) -> NINGBO CIMEI IMPORT & EXPORT CO., LTD
D11: =_xlfn.XLOOKUP(A1,'Contract Data'!C:C,'Contract Data'!J:J)&_xlfn.XLOOKUP(A1,'Contract Data'!C:C,'Contract Data'!K:K) -> 18F, Block A, Ningxing International Trade Building, 510 Heyuan Road,Yinzhou District, Ningbo, 315040, P.R.C
D12: =_xlfn.XLOOKUP(A1,'Contract Data'!C:C,'Contract Data'!P:P)&""&_xlfn.XLOOKUP(A1,'Contract Data'!C:C,'Contract Data'!R:R)&""&_xlfn.XLOOKUP(A1,'Contract Data'!C:C,'Contract Data'!Q:Q) -> 91330201698240267Gamy.jiang@futureie.comTel: 0086-574-87780225
D13: WE CONFIRM HAVING SOLD TO YOU THE FOLLOWING:
D15: 1. | E15: COMMODITY
E16: 1.1. | F16: =_xlfn.XLOOKUP(A1,'Contract Data'!C:C,'Contract Data'!S:S) -> COPPER INGOTS 99%
E17: 1.2. | F17: THE CONSIGNMENT DOES NOT CONTAIN ANY TYPE OF ARMS, AMMUNITIONS, MINES, SHELLS, HAZARDOUS WASTE, CARTRIDGES, RADIOACTIVE CONTAMINATED OR ANY OTHER EXPLOSIVE OR PROHIBITED MATERIAL IN ANY FORM, WHETHER USED OR UNUSED, AND IS SAFE FOR TRANSPORT AND HANDLING.
E18: 1.3. | F18: ORIGIN : | H18: =_xlfn.XLOOKUP(A1,'Contract Data'!C:C,'Contract Data'!U:U) -> PAKISTAN
E19: 1.4. | F19: LOAD PORT : | H19: ="ANY PORT (S) IN "&_xlfn.XLOOKUP(A1,'Contract Data'!C:C,'Contract Data'!V:V) -> ANY PORT (S) IN PAKISTAN
E20: 1.5. | F20: PLACE OF DELIVERY : | H20: =_xlfn.XLOOKUP(A1,'Contract Data'!C:C,'Contract Data'!Z:Z)&", "&_xlfn.XLOOKUP(A1,'Contract Data'!C:C,'Contract Data'!W:W)&_xlfn.XLOOKUP(A1,'Contract Data'!C:C,'Contract Data'!X:X)&", "&_xlfn.XLOOKUP(A1,'Contract Data'!C:C,'Contract Data'!L:L) -> CIF, NINGBO,, CHINA
E21: 1.6. | F21: QUANTITY & PACKING: | H21: =_xlfn.XLOOKUP(A1,'Contract Data'!C:C,'Contract Data'!AA:AA)&" MT "&_xlfn.XLOOKUP(A1,'Contract Data'!C:C,'Contract Data'!AB:AB)&" (SELLER’S OPTION) IN "&_xlfn.XLOOKUP(A1,'Contract Data'!C:C,'Contract Data'!AC:AC)&" IN "&_xlfn.XLOOKUP(A1,'Contract Data'!C:C,'Contract Data'!AD:AD)&" X "&_xlfn.XLOOKUP(A1,'Contract Data'!C:C,'Contract Data'!AE:AE)&" CONTAINER/S" -> 100 MT +/-10% (SELLER’S OPTION) IN LOSSE IN 5 X 20 CONTAINER/S
D23: 2. | E23: PAYMENT CONDITIONS : | H23: =_xlfn.XLOOKUP(A1,'Contract Data'!C:C,'Contract Data'!AF:AF)&" AGAINST FOLLOWING DOCUMENTS" -> 100% CAD THROUGH BANK AGAINST FOLLOWING DOCUMENTS
E24: =_xlfn.XLOOKUP(A1,'Contract Data'!C:C,'Contract Data'!AG:AG) -> 1) FULL SET (3/3) ORIGINAL BILL OF LADING B/L TO SHOW "FREIGHT PREPAID" 2) COMMERCIAL INVOICE 3) PACKING LIST 4) CERTIFICATE OF ORIGIN 5) INSURANCE CERTIFICATE.
D26: 3. | E26: ="PRICE: "&_xlfn.XLOOKUP('CHINA (QP)'!A1,'Contract Data'!C:C,'Contract Data'!AH:AH)&",TO BE FIXED BY BUYER, EITHER ON OFFICIAL SETTLEMENT OR ON RUNNING SCREEN OR GTC WITHIN SPECIFIED Q/P X "&_xlfn.XLOOKUP(A1,'Contract Data'!C:C,'Contract Data'!AI:AI)&" %"&" "&_xlfn.XLOOKUP(A1,'Contract Data'!C:C,'Contract Data'!Z:Z)&" "&_xlfn.XLOOKUP(A1,'Contract Data'!C:C,'Contract Data'!W:W)&_xlfn.XLOOKUP(A1,'Contract Data'!C:C,'Contract Data'!X:X)&", "&_xlfn.XLOOKUP(A1,'Contract Data'!C:C,'Contract Data'!L:L) -> PRICE: 3 MONTHS CU LME IN US$ ,TO BE FIXED BY BUYER, EITHER ON OFFICIAL SETTLEMENT OR ON RUNNING SCREEN OR GTC WITHIN SPECIFIED Q/P X 96.85 % CIF NINGBO,, CHINA
D28: 4. | E28: Q/P: ANY UNKNOWN LME WORKING DAY, FROM BUSINESS CONFIRMATION DATE TILL ETA.
D30: 5. | E30: SHIPMENT PERIOD: LOADING WILL BE WITHIN 45 DAYS FROM THE DATE OF RECEIPT OF SIGNED CONTRACT AND ADVANCE PAYMENT IN OUR ACCOUNT (IF APPLICABLE), SHIPMENT WILL BE ON 1ST AVAILABLE VESSEL (SUBJECT TO NO LOCKDOWN OR ANY UNFORESEEN CIRCUMSTANCES AT POL).
D32: 6. | E32: INSURANCE: THE SELLER SHALL COVER THE INSURANCE AT THEIR COST. THE INSURANCE CLAUSE SHOULD BE AS UNDER: “MARINE INSURANCE POLICY / CERTIFICATE FOR ATLEAST 10% OVER THE INVOICE VALUE, DATED NOT LATER THAN THE DATE OF BILL OF LADING COVERING INSTITUTE CARGO CLAUSE [A]” WITH COVERAGE FOR THE THEFT AND PILFERAGE.
D33: 7. | E33: ARBITRATION AND GOVERNING LAW: ANY DISPUTES ARISING OUT OF OR IN CONNECTION WITH THIS CONTRACT, INCLUDING ANY QUESTION REGARDING ITS EXECUTION, VALIDITY OR TERMINATION, WHICH THE PARTIES FAIL TO RESOLVE AMICABLY, SHALL BE REFERRED TO AND FINALLY RESOLVED BY ARBITRATION UNDER THE SIAC (SINGAPORE INTERNATIONAL ARBITRATION CENTRE) OR DIFC (DUBAI INTERNATIONAL FINANCIAL CENTRE) OR LCIA (THE LONDON COURT OF INTERNATIONAL ARBITRATION) ON THIS SUBJECT.
D34: 8. | E34: FORCE MAJEURE: SUCH AS FIRE, FLOOD, BREAKDOWN, ACCIDENT, WAR, INSURRECTION, RIOT, GOVERNMENTAL ACTION, LABOR DISPUTE, SHORTAGE OF FUEL, ELECTRICITY, RAW MATERIALS OR SUPPLIES, LACK OF FREIGHT FACILITIES, CAUSED BY ANY ACT OF GOD OR ANY OTHER CAUSE BEYOND THE REASONABLE CONTROL OF THE SELLER OR ADANI GLOBAL FZE, THE ARRANGEMENTS AND OBLIGATIONS OF THE CONTRACT ARE SUSPENDED COMPLETELY OR PARTIALLY, DEPENDING ON THE EXTENT OF THE HINDRANCE, FOR THE DURATION OF THE FORCE MAJEURE FROM THE MOMENT IN WHICH THE AFFECTED PARTY INFORMS THE OTHER ABOUT THE EXISTENCE OF FORCE MAJEURE IN WRITING, INCLUDING THE REASON FOR IT.
D37: اداني دجلوبال م م ح
D38: Adani Global FZE | G38: Tel: +971 4 3611900
D39: Post Box 17186, | G39: Fax: +971 4 3689600
D40: Jebel Ali, | G40: Email: commercial.dxb@adani.in
D41: Dubai, UAE | G41: www.adani.com
D43: ذات مسئولية محدودة تأسست بموجب القانون رقم 9 لسنة 1992
D44: Formed pursuant to Law No.9 of 1992 With Limited Liability
D53: =D8 -> S/AGFZE/CU/NC/004/2026-27 | O53: =O8 -> DATE: 06/06/2026
E55: IN THE CASE OF FORCE MAJEURE AT ADANI GLOBAL FZE, DELIVERIES ARE ONLY PERMITTED WITH ADANI GLOBAL FZE EXPRESS AGREEMENT. A SUSPENSION OF PERFORMANCE SHALL NOT HAVE THE EFFECT OF CANCELLING THE CONTRACT, WHICH SHALL AGAIN COME INTO FULL FORCE AND EFFECT IMMEDIATELY UPON TERMINATION OF THE FORCE MAJEURE EVENT. THE CONTRACT SHALL, EACH TIME, BE EXTENDED FOR A PERIOD EQUAL TO THE PERIOD OF SUSPENSION.
E56: IF A CASE OF FORCE MAJEURE LASTS LONGER THAN THREE MONTHS FROM THE TIME IT IS ANNOUNCED, EACH SELLER HAS THE RIGHT TO RESCIND THE CONTRACT WITH RESPECT TO THE VOLUMES THAT WERE NOT DELIVERED AND/OR ACCEPTED DUE TO THE FORCE MAJEURE.
E57: NOTWITHSTANDING THE FOREGOING PROVISIONS SHOULD THE PRICE OF THE METALS, WHICH DELIVERY WAS SUSPENDED DUE TO AN EVENT OF FORCE MAJEURE, HAVE ALREADY BEEN FIXED, THEN SUCH PRICE IS APPLIED TO THE MATERIAL TO BE FIRST DELIVERED AFTER THE DELIVERY THEREOF IS RESUMED.
D59: 9. | E59: IF THERE IS A VARIATION IN THE QUALITY AND QUANTITY AT DISCHARGE PORT, A THIRD PARTY MUTUALLY AGREED INSPECTION AGENCY WILL BE APPOINTED AND THEIR RESULT WILL BE TAKEN AS A FINAL AND LOOSING PARTY WILL PAY THE CHARGES AND SETTLE THE CLAIM TO BUYER / SELLER.
D61: 10. | E61: ALL KIND OF TAXES / DUTIES/LEVIES ETC. IN IMPORTING COUNTRY TO BE BORNE BY THE BUYER.
D63: 11. | E63: ="WEIGHT SHORTAGE WILL NOT BE ACCEPTED LESS THAN "&_xlfn.XLOOKUP(A1,'Contract Data'!C:C,'Contract Data'!AK:AK)&", MORE THAN "&_xlfn.XLOOKUP(A1,'Contract Data'!C:C,'Contract Data'!AK:AK)&" WILL BE CLAIMED" -> WEIGHT SHORTAGE WILL NOT BE ACCEPTED LESS THAN 0.50%, MORE THAN 0.50% WILL BE CLAIMED
D65: 12. | E65: ALL BANK CHARGES OUTSIDE UAE INCLUDING CORRESPONDENCE BANK CHARGES WILL BE IN BUYER'S ACCOUNT, ACTUAL AMOUNT RECEIVED THROUGH ADVANCE / DEPOSIT WILL BE CONSIDERED AND ADJUSTED IN THE INVOICE ACCORDINGLY.
D67: 13. | E67: US SANCTIONS COMPLIANCE: EACH PARTY REPRESENTS AND WARRANTS THAT IT IS NOT A SANCTIONED PERSON AND SHALL COMPLY WITH ALL APPLICABLE U.S. SANCTIONS LAWS AND REGULATIONS. NEITHER PARTY SHALL ENGAGE IN ANY TRANSACTION UNDER THIS CONTRACT THAT WOULD CAUSE EITHER PARTY TO VIOLATE U.S. SANCTIONS, INCLUDING DEALINGS WITH SANCTIONED ENTITIES OR RESTRICTED JURISDICTIONS. IF COMPLIANCE BECOMES UNLAWFUL, THE AFFECTED PARTY MAY SUSPEND OR TERMINATE PERFORMANCE WITHOUT LIABILITY.
D70: THE SELLER | N70: THE BUYER
D72: FOR ADANI GLOBAL FZE. | N72: ="FOR "&D10 -> FOR NINGBO CIMEI IMPORT & EXPORT CO., LTD
...

Sheet CHINA (FIXED RATE)
A1: 004
D6: SALES CONTRACT
D8: =_xlfn.XLOOKUP(A1,'Contract Data'!C:C,'Contract Data'!I:I) -> S/AGFZE/CU/NC/004/2026-27 | O8: ="DATE: "&TEXT(_xlfn.XLOOKUP(A1,'Contract Data'!C:C,'Contract Data'!D:D),"dd/mm/yyyy") -> DATE: 06/06/2026
D10: =_xlfn.XLOOKUP(A1,'Contract Data'!C:C,'Contract Data'!H:H) -> NINGBO CIMEI IMPORT & EXPORT CO., LTD
D11: =_xlfn.XLOOKUP(A1,'Contract Data'!C:C,'Contract Data'!J:J)&_xlfn.XLOOKUP(A1,'Contract Data'!C:C,'Contract Data'!K:K) -> 18F, Block A, Ningxing International Trade Building, 510 Heyuan Road,Yinzhou District, Ningbo, 315040, P.R.C
D12: =_xlfn.XLOOKUP(A1,'Contract Data'!C:C,'Contract Data'!P:P)&""&_xlfn.XLOOKUP(A1,'Contract Data'!C:C,'Contract Data'!R:R)&""&_xlfn.XLOOKUP(A1,'Contract Data'!C:C,'Contract Data'!Q:Q) -> 91330201698240267Gamy.jiang@futureie.comTel: 0086-574-87780225
D13: WE CONFIRM HAVING SOLD TO YOU THE FOLLOWING:
D15: 1. | E15: COMMODITY
E16: 1.1. | F16: =_xlfn.XLOOKUP(A1,'Contract Data'!C:C,'Contract Data'!S:S) -> COPPER INGOTS 99%
E17: 1.2. | F17: THE CONSIGNMENT DOES NOT CONTAIN ANY TYPE OF ARMS, AMMUNITIONS, MINES, SHELLS, HAZARDOUS WASTE, CARTRIDGES, RADIOACTIVE CONTAMINATED OR ANY OTHER EXPLOSIVE OR PROHIBITED MATERIAL IN ANY FORM, WHETHER USED OR UNUSED, AND IS SAFE FOR TRANSPORT AND HANDLING.
E18: 1.3. | F18: ORIGIN : | H18: =_xlfn.XLOOKUP(A1,'Contract Data'!C:C,'Contract Data'!U:U) -> PAKISTAN
E19: 1.4. | F19: LOAD PORT : | H19: ="ANY PORT (S) IN "&_xlfn.XLOOKUP(A1,'Contract Data'!C:C,'Contract Data'!V:V) -> ANY PORT (S) IN PAKISTAN
E20: 1.5. | F20: PLACE OF DELIVERY : | H20: =_xlfn.XLOOKUP(A1,'Contract Data'!C:C,'Contract Data'!Z:Z)&", "&_xlfn.XLOOKUP(A1,'Contract Data'!C:C,'Contract Data'!W:W)&_xlfn.XLOOKUP(A1,'Contract Data'!C:C,'Contract Data'!X:X)&", "&_xlfn.XLOOKUP(A1,'Contract Data'!C:C,'Contract Data'!L:L) -> CIF, NINGBO,, CHINA
E21: 1.6. | F21: QUANTITY & PACKING : | H21: =_xlfn.XLOOKUP(A1,'Contract Data'!C:C,'Contract Data'!AA:AA)&" MT "&_xlfn.XLOOKUP(A1,'Contract Data'!C:C,'Contract Data'!AB:AB)&" (SELLER’S OPTION) IN "&_xlfn.XLOOKUP(A1,'Contract Data'!C:C,'Contract Data'!AC:AC)&" IN "&_xlfn.XLOOKUP(A1,'Contract Data'!C:C,'Contract Data'!AD:AD)&" X "&_xlfn.XLOOKUP(A1,'Contract Data'!C:C,'Contract Data'!AE:AE)&" CONTAINER/S" -> 100 MT +/-10% (SELLER’S OPTION) IN LOSSE IN 5 X 20 CONTAINER/S
D23: 2. | E23: PAYMENT CONDITIONS : | H23: =_xlfn.XLOOKUP(A1,'Contract Data'!C:C,'Contract Data'!AF:AF)&" AGAINST FOLLOWING DOCUMENTS" -> 100% CAD THROUGH BANK AGAINST FOLLOWING DOCUMENTS
E24: =_xlfn.XLOOKUP(A1,'Contract Data'!C:C,'Contract Data'!AG:AG) -> 1) FULL SET (3/3) ORIGINAL BILL OF LADING B/L TO SHOW "FREIGHT PREPAID" 2) COMMERCIAL INVOICE 3) PACKING LIST 4) CERTIFICATE OF ORIGIN 5) INSURANCE CERTIFICATE.
D26: 3. | E26: ="PRICE: USD "&_xlfn.XLOOKUP(A1,'Contract Data'!C:C,'Contract Data'!AJ:AJ)&" PMT" &", "&_xlfn.XLOOKUP(A1,'Contract Data'!C:C,'Contract Data'!Z:Z)&" "&_xlfn.XLOOKUP(A1,'Contract Data'!C:C,'Contract Data'!W:W)&","&_xlfn.XLOOKUP(A1,'Contract Data'!C:C,'Contract Data'!X:X)&" "&_xlfn.XLOOKUP(A1,'Contract Data'!C:C,'Contract Data'!L:L) -> PRICE: USD 5000 PMT, CIF NINGBO,, CHINA
D28: 4. | E28: SHIPMENT PERIOD: LOADING WILL BE WITHIN 45 DAYS FROM THE DATE OF RECEIPT OF SIGNED CONTRACT AND ADVANCE PAYMENT IN OUR ACCOUNT (IF APPLICABLE), SHIPMENT WILL BE ON 1ST AVAILABLE VESSEL (SUBJECT TO NO LOCKDOWN OR ANY UNFORESEEN CIRCUMSTANCES AT POL).
D30: 5. | E30: INSURANCE: THE SELLER SHALL COVER THE INSURANCE AT THEIR COST. THE INSURANCE CLAUSE SHOULD BE AS UNDER: “MARINE INSURANCE POLICY / CERTIFICATE FOR ATLEAST 10% OVER THE INVOICE VALUE, DATED NOT LATER THAN THE DATE OF BILL OF LADING COVERING INSTITUTE CARGO CLAUSE [A]” WITH COVERAGE FOR THE THEFT AND PILFERAGE.
D31: 6. | E31: ARBITRATION AND GOVERNING LAW: ANY DISPUTES ARISING OUT OF OR IN CONNECTION WITH THIS CONTRACT, INCLUDING ANY QUESTION REGARDING ITS EXECUTION, VALIDITY OR TERMINATION, WHICH THE PARTIES FAIL TO RESOLVE AMICABLY, SHALL BE REFERRED TO AND FINALLY RESOLVED BY ARBITRATION UNDER THE SIAC (SINGAPORE INTERNATIONAL ARBITRATION CENTRE) OR DIFC (DUBAI INTERNATIONAL FINANCIAL CENTRE) OR LCIA (THE LONDON COURT OF INTERNATIONAL ARBITRATION) ON THIS SUBJECT.
D32: 7. | E32: FORCE MAJEURE: SUCH AS FIRE, FLOOD, BREAKDOWN, ACCIDENT, WAR, INSURRECTION, RIOT, GOVERNMENTAL ACTION, LABOR DISPUTE, SHORTAGE OF FUEL, ELECTRICITY, RAW MATERIALS OR SUPPLIES, LACK OF FREIGHT FACILITIES, CAUSED BY ANY ACT OF GOD OR ANY OTHER CAUSE BEYOND THE REASONABLE CONTROL OF THE SELLER OR ADANI GLOBAL FZE, THE ARRANGEMENTS AND OBLIGATIONS OF THE CONTRACT ARE SUSPENDED COMPLETELY OR PARTIALLY, DEPENDING ON THE EXTENT OF THE HINDRANCE, FOR THE DURATION OF THE FORCE MAJEURE FROM THE MOMENT IN WHICH THE AFFECTED PARTY INFORMS THE OTHER ABOUT THE EXISTENCE OF FORCE MAJEURE IN WRITING, INCLUDING THE REASON FOR IT.
D35: اداني دجلوبال م م ح
D36: Adani Global FZE | G36: Tel: +971 4 3611900
D37: Post Box 17186, | G37: Fax: +971 4 3689600
D38: Jebel Ali, | G38: Email: commercial.dxb@adani.in
D39: Dubai, UAE | G39: www.adani.com
D41: ذات مسئولية محدودة تأسست بموجب القانون رقم 9 لسنة 1992
D42: Formed pursuant to Law No.9 of 1992 With Limited Liability
D51: =D8 -> S/AGFZE/CU/NC/004/2026-27 | O51: =O8 -> DATE: 06/06/2026
E53: IN THE CASE OF FORCE MAJEURE AT ADANI GLOBAL FZE, DELIVERIES ARE ONLY PERMITTED WITH ADANI GLOBAL FZE EXPRESS AGREEMENT. A SUSPENSION OF PERFORMANCE SHALL NOT HAVE THE EFFECT OF CANCELLING THE CONTRACT, WHICH SHALL AGAIN COME INTO FULL FORCE AND EFFECT IMMEDIATELY UPON TERMINATION OF THE FORCE MAJEURE EVENT. THE CONTRACT SHALL, EACH TIME, BE EXTENDED FOR A PERIOD EQUAL TO THE PERIOD OF SUSPENSION.
E54: IF A CASE OF FORCE MAJEURE LASTS LONGER THAN THREE MONTHS FROM THE TIME IT IS ANNOUNCED, EACH SELLER HAS THE RIGHT TO RESCIND THE CONTRACT WITH RESPECT TO THE VOLUMES THAT WERE NOT DELIVERED AND/OR ACCEPTED DUE TO THE FORCE MAJEURE.
E55: NOTWITHSTANDING THE FOREGOING PROVISIONS SHOULD THE PRICE OF THE METALS, WHICH DELIVERY WAS SUSPENDED DUE TO AN EVENT OF FORCE MAJEURE, HAVE ALREADY BEEN FIXED, THEN SUCH PRICE IS APPLIED TO THE MATERIAL TO BE FIRST DELIVERED AFTER THE DELIVERY THEREOF IS RESUMED.
D57: 8. | E57: IF THERE IS A VARIATION IN THE QUALITY AND QUANTITY AT DISCHARGE PORT, A THIRD PARTY MUTUALLY AGREED INSPECTION AGENCY WILL BE APPOINTED AND THEIR RESULT WILL BE TAKEN AS A FINAL AND LOOSING PARTY WILL PAY THE CHARGES AND SETTLE THE CLAIM TO BUYER / SELLER.
D59: 9. | E59: ALL KIND OF TAXES / DUTIES/LEVIES ETC. IN IMPORTING COUNTRY TO BE BORNE BY THE BUYER.
D61: 10. | E61: ="WEIGHT SHORTAGE WILL NOT BE ACCEPTED LESS THAN "&_xlfn.XLOOKUP(A1,'Contract Data'!C:C,'Contract Data'!AK:AK)&", MORE THAN "&_xlfn.XLOOKUP(A1,'Contract Data'!C:C,'Contract Data'!AK:AK)&" WILL BE CLAIMED" -> WEIGHT SHORTAGE WILL NOT BE ACCEPTED LESS THAN 0.50%, MORE THAN 0.50% WILL BE CLAIMED
D63: 11. | E63: ALL BANK CHARGES OUTSIDE UAE INCLUDING CORRESPONDENCE BANK CHARGES WILL BE IN BUYER'S ACCOUNT, ACTUAL AMOUNT RECEIVED THROUGH ADVANCE / DEPOSIT WILL BE CONSIDERED AND ADJUSTED IN THE INVOICE ACCORDINGLY.
D65: 12. | E65: US SANCTIONS COMPLIANCE: EACH PARTY REPRESENTS AND WARRANTS THAT IT IS NOT A SANCTIONED PERSON AND SHALL COMPLY WITH ALL APPLICABLE U.S. SANCTIONS LAWS AND REGULATIONS. NEITHER PARTY SHALL ENGAGE IN ANY TRANSACTION UNDER THIS CONTRACT THAT WOULD CAUSE EITHER PARTY TO VIOLATE U.S. SANCTIONS, INCLUDING DEALINGS WITH SANCTIONED ENTITIES OR RESTRICTED JURISDICTIONS. IF COMPLIANCE BECOMES UNLAWFUL, THE AFFECTED PARTY MAY SUSPEND OR TERMINATE PERFORMANCE WITHOUT LIABILITY.
D68: THE SELLER | N68: THE BUYER
D70: FOR ADANI GLOBAL FZE. | N70: ="FOR "&D10 -> FOR NINGBO CIMEI IMPORT & EXPORT CO., LTD
D74: AUTHORIZED SIGNATORY | N74: AUTHORIZED SIGNATORY
...

Sheet PERFORMA INVOICE
A1: 002
D10: =_xlfn.XLOOKUP(A1,'Contract Data'!C:C,'Contract Data'!I:I) -> S/AGFZE/AL/PO/002/2026-27 | O10: ="DATE: "&TEXT(_xlfn.XLOOKUP(A1,'Contract Data'!C:C,'Contract Data'!D:D),"dd/mm/yyyy") -> DATE: 08/04/2026
D12: =_xlfn.XLOOKUP(A1,'Contract Data'!C:C,'Contract Data'!H:H) -> PARAS OVERSEAS
D13: =_xlfn.XLOOKUP(A1,'Contract Data'!C:C,'Contract Data'!J:J)&_xlfn.XLOOKUP(A1,'Contract Data'!C:C,'Contract Data'!K:K) -> 1008, 10TH FLOOR, SUKHSAGAR COMPLEX, FORTUNE LANDMARK HOTEL, USMANPURA-380013, AHMEDABAD, INDIA
D14: =_xlfn.XLOOKUP(A1,'Contract Data'!C:C,'Contract Data'!M:M)&", "&_xlfn.XLOOKUP(A1,'Contract Data'!C:C,'Contract Data'!N:N)&", "&_xlfn.XLOOKUP(A1,'Contract Data'!C:C,'Contract Data'!O:O)&", "&_xlfn.XLOOKUP(A1,'Contract Data'!C:C,'Contract Data'!R:R)&", "&_xlfn.XLOOKUP(A1,'Contract Data'!C:C,'Contract Data'!Q:Q) -> IEC: 0814022944, PAN: AAQFP6007J, GST: 24AAQFP6007J1Z1, EMAIL: JAINAM@PARASGROUPS.IN, TEL: +91-9978050608
D17: PERFORMA INVOICE
D20: ITEM DESCRIPTION | J20: QTY | L20: PRICE (USD) | O20: AMOUNT USD
D22: =_xlfn.XLOOKUP(A1,'Contract Data'!C:C,'Contract Data'!S:S) -> ALUMINIUM SCRAP TALLY AS PER ISRI | J22: =_xlfn.XLOOKUP(A1,'Contract Data'!C:C,'Contract Data'!AA:AA) -> 21 | L22: 8600 | O22: =J22*L22 -> 180600
D25: ADVANCE 10% | O25: =O22*10% -> 18060
D27: PAYMENT TERAM | G27: =_xlfn.XLOOKUP(A1,'Contract Data'!C:C,'Contract Data'!AF:AF) -> 100% CAD THROUGH BANK
D29: BANK DETAILS USD:
D30: BENEFICIARY NAME | I30: : | J30: ADANI GLOBAL FZE
D31: IBAN NO | I31: : | J31: AE09 0960 0000 1101 0000 002
D32: BENEFICIARY BANK | I32: : | J32: ZAND BANK PJSC, EMAAR SQUAR, DUBAI, U.A.E.
D33: BENEFICIARY BANK SWIFT CODE | I33: : | J33: ZANDAEAA
D34: CORRESPONDENT BANK NAME | I34: : | J34: THE BANK OF NEW YORK MELLON
D35: SWIFT CODE | I35: : | J35: IRVTUS3NXXX
D38: ALL TERMS AND CONDITIONS AS PER THE CONTRACT NO. | L38: =D10&" "&O10 -> S/AGFZE/AL/PO/002/2026-27 DATE: 08/04/2026
D40: FOR ADANI GLOBAL FZE.
D44: AUTHORIZED SIGNATORY
D46: اداني دجلوبال م م ح
D47: Adani Global FZE | G47: Tel: +971 4 3611900
D48: Post Box 17186, | G48: Fax: +971 4 3689600
D49: Jebel Ali, | G49: Email: commercial.dxb@adani.in
D50: Dubai, UAE | G50: www.adani.com
D52: ذات مسئولية محدودة تأسست بموجب القانون رقم 9 لسنة 1992
D53: Formed pursuant to Law No.9 of 1992 With Limited Liability
D58: HABIB
D60: BANK DETAILS USD:
D61: BENEFICIARY NAME | I61: : | J61: ADANI GLOBAL FZE
D62: ACCOUNT NUMBER | I62: : | J62: 02-01-02-020430-333-0181868
D63: IBAN NO | I63: : | J63: AE13 0290 2204 3033 3181 868
D64: BENEFICIARY BANK | I64: : | J64: HABIB BANK AG ZURICH, MAIN BRANCH, KHALID BIN WALEED STREET, DUBAI, U.A.E
D65: BENEFICIARY BANK SWIFT CODE | I65: : | J65: HBZUAEADXXX
D66: CORRESPONDENT BANK NAME | I66: : | J66: HABIB AMERICAN BANK, USA
D67: SWIFT CODE | I67: : | J67: HANYUS33XXX
D71: ZAND
D73: BANK DETAILS USD:
D74: BENEFICIARY NAME | I74: : | J74: ADANI GLOBAL FZE
D75: ACCOUNT NUMBER | I75: :
...

Sheet Sheet1
